Workbook

Sheet 存量房抵押
A1: 序号 | B1: 封包号 | C1: 业务合同编号 | D1: 借款人 | E1: 抵押人 | F1: 贷种 | G1: 不动产证明 | H1: 抵押金额 （万元） | I1: 借款期限 | J1: 抵押贷款时间 | K1: 到期日期 | L1: 客户经理
A2: 1 | B2: 20210430043600006304001 | C2: 360102782210404116613 | D2: 彭康腾 | E2: 彭康腾 戴丽霞 | F2: 商贷通 | G2: 赣（2021）吉安市不产证明第0015193号 | H2: 130 | I2: 10 | J2: 44313 | K2: 47965
A3: 2 | B3: 20210430043600006304002 | C3: 360103042210400994428 | D3: 陈珍贵 | E3: 陈珍贵 李小兵 | F3: 极速贷 | G3: 赣（2021）吉安市不产证明第0015461号 | H3: 35 | I3: 10 | J3: 44312 | K3: 47964
A4: 3 | B4: 20210508043600006304002 | C4: 36010304221040060168 | D4: 肖承斌 | E4: 肖承斌 胡永梅 | F4: 极速贷 | G4: 赣（2021）吉安市不产证明第0015680号 | H4: 35 | I4: 10 | J4: 44312 | K4: 47964
A5: 4 | B5: 20210508043600006304003 | C5: 3699950Q221050313026 | D5: 陶观青 | E5: 陶观青 涂时风 | F5: 网商贷 | G5: 赣（2021）吉安市不产证明第0016091号 | H5: 110 | I5: 10 | J5: 44323 | K5: 47975
A6: 5 | B6: 20210508043600006304004 | C6: 3699950Q221050250847 | D6: 周慎泰 | E6: 刘爱群 | F6: 极速贷 | G6: 赣（2021）吉安市不产证明第0015886号 | H6: 41 | I6: 10 | J6: 44321 | K6: 47973
A7: 6 | B7: 20210508043600006304005 | C7: 3699950Q1040177766 | D7: 程浩 | E7: 程浩 杨希 | F7: 网商贷 | G7: 赣（2021）吉安市不产证明第0015787号 | H7: 23 | I7: 10 | J7: 44315 | K7: 47967
A8: 7 | B8: 20210510043600006304001 | C8: 3699950Q221050311993 | D8: 易云清 | E8: 易云清 易彩秋 | F8: 网商贷 | G8: 赣（2021）吉安市不产证明第0016205号 | H8: 66 | I8: 10 | J8: 44323 | K8: 47975
A9: 8 | B9: 20210510043600006304002 | C9: 3699950Q221050288004 | D9: 戴利平 | E9: 戴利平 | F9: 网商贷 | G9: 赣（2021）吉安市不产证明第0016126号 | H9: 52 | I9: 10 | J9: 44322 | K9: 47974
A10: 9 | B10: 20210510043600006304003 | C10: 36010278221050306845 | D10: 王晓东 | E10: 王晓东 | F10: 商贷通 | G10: 赣（2021）吉安市不产证明第0016124号 | H10: 49 | I10: 10 | J10: 44323 | K10: 47975
A11: 10 | B11: 20210510043699950Q05001 | C11: 3699950Q1050287142 | D11: 刘婷 | E11: 刘婷 肖安亮 | F11: 个人二手房贷款 | G11: 赣（2021）吉安市不产证明第0016179号 | H11: 33 | I11: 30 | J11: 44324 | K11: 55281
A12: 11 | B12: 20210511043600006304003 | C12: 36010304221050358634 | D12: 胡艳珺 | E12: 胡铭珺 罗镕荣 | F12: 极速贷 | G12: 赣（2021）吉安市不产证明第0016235号 | H12: 50 | I12: 10 | J12: 44325 | K12: 47977
A13: 12 | B13: 20210511043600006304001 | C13: 36010278221050347481 | D13: 刘玉珍 | E13: 刘玉珍 张震 | F13: 商贷通 | G13: 赣（2021）吉安市不产证明第0016233号 | H13: 75 | I13: 10 | J13: 44324 | K13: 47976
... A25: 24 | B25: 20210525043600006304001 | C25: 3699950Q221050753606 | D25: 胡喆 | E25: 胡喆 | F25: 商贷通 | G25: 赣（2021）吉安市不产证明第0017674号 | H25: 62 | I25: 10 | J25: 44337 | K25: 47989
A26: 25 | B26: 20210526043699950Q05001 | C26: 3699950Q117035809963 | D26: 李安军 | E26: 李安军 刘正华 | F26: 一手房(转抵押) | G26: 赣（2021）吉安市不产证明第0017173号 | H26: 35 | I26: 10 | J26: 42817 | K26: 46469 | L26: 严姝玲
A27: 26 | B27: 20210527043600006304002 | C27: 3699950Q221050820273 | D27: 夏安平 | E27: 夏安平 徐婷 | F27: 网商贷 | G27: 赣（2021）吉安市不产证明第0017770号 | H27: 40 | I27: 10 | J27: 44340 | K27: 47992
A28: 27 | B28: 20210527043600006305003 | C28: 369995Q121054914405 | D28: 刘春燕 | E28: 刘春燕 | F28: 个人二手房贷款 | G28: 赣（2021）吉安市不产证明第0017991号 | H28: 35 | I28: 10 | J28: 44256 | K28: 46447
A29: 28 | B29: 20210528043601030405001 | C29: 36010316115070170003 | D29: 曾苏珍 | E29: 曾苏珍 | F29: 一手房(转抵押) | G29: 赣（2021）吉安市不动产证明第0016227号 | H29: 370000 | I29: 曾苏珍、薛涛 | J29: 42191 | K29: 47666 | L29: 万淑红
A30: 29 | B30: 20210528043601030405002 | C30: 36010316115070192366 | D30: 梁昌尧 | E30: 梁昌尧 | F30: 一手房(转抵押) | G30: 赣（2021）吉安市不动产证明第0016229号 | H30: 280000 | I30: 梁昌尧 | J30: 42195 | K30: 49500 | L30: 万淑红
A31: 30 | B31: 20210528043601030405003 | C31: 36010316115100946209 | D31: 温永佑 | E31: 温永佑 | F31: 一手房(转抵押) | G31: 赣（2021）吉安市不动产证明第0016232号 | H31: 230000 | I31: 温永佑、陈琼玉 | J31: 42292 | K31: 53250 | L31: 万淑红
A32: 31 | B32: 20210528043601030405004 | C32: 36010316115090588595 | D32: 许艳琼 | E32: 许艳琼 | F32: 一手房(转抵押) | G32: 赣（2021）吉安市不动产证明第0016228号 | H32: 290000 | I32: 许艳琼 | J32: 42243 | K32: 49548 | L32: 万淑红
A33: 32 | B33: 20210528043601030405008 | C33: 36010304121043623281 | D33: 陈仁慧 | E33: 陈仁慧 | F33: 一手房(转抵押) | G33: 赣（2021）吉安市不产证明第0014177号 | H33: 140000 | I33: 陈仁慧 | J33: 44308 | K33: 47960 | L33: 万淑红
A34: 33 | B34: 20210528043601030405009 | C34: 36010304121043630121 | D34: 熊琴 | E34: 熊琴 | F34: 一手房(转抵押) | G34: 赣（2021）吉安市不产证明第0013593号 | H34: 360000 | I34: 熊琴/田海 | J34: 44295 | K34: 47947 | L34: 万淑红
A35: 34 | B35: 20210528043601030405010 | C35: 3601030412104362094701 | D35: 郭群 | E35: 郭群 | F35: 一手房(转抵押) | G35: 赣（2021）吉安市不产证明第0017817号 | H35: 145000 | I35: 郭群 | J35: 44298 | K35: 47950
A36: 35 | B36: 20210528043601030405011 | C36: 3601030412104358372101 | D36: 谢启发 | E36: 谢启发 | F36: 一手房(转抵押) | G36: 赣（2021）吉安市不产证明第0016415号 | H36: 750000 | I36: 谢启发 | J36: 44294 | K36: 55251
A37: 36 | B37: 20210528043699950Q05001 | C37: 36010304121054370132 | D37: 林水凤 | E37: 林水凤 | F37: 一手房(转抵押) | G37: 赣（2021）吉安市不产证明第0016722号 | H37: 720000 | I37: 孙武堃/林水凤 | J37: 44333 | K37: 47985 | L37: 郭元
A38: 37 | B38: 20210528043601030405012 | C38: 3601030412104362328101 | D38: 赵琪 | E38: 赵琪 | F38: 一手房(转抵押) | G38: 赣（2021）吉安市不产证明第0014171号 | H38: 145000 | I38: 赵琪 | J38: 44301 | K38: 47953
A39: 38 | B39: 20210528043601030405013 | C39: 36010304121044143510 | D39: 李玲 | E39: 李玲 | F39: 一手房(转抵押) | G39: 赣（2021）吉安市不产证明第0017794号 | H39: 143000 | I39: 李玲 | J39: 44337 | K39: 47989 | L39: 万淑红
A40: 39 | B40: 20210528043601030405005 | C40: 36010304121033376725 | D40: 雷慧玲 | E40: 雷慧玲 | F40: 一手房(转抵押) | G40: 赣（2021）吉安市不动产证明第0013589号 | H40: 140000 | I40: 雷慧玲 | J40: 44286 | K40: 47938 | L40: 万淑红
A41: 40 | B41: 20210528043601030405006 | C41: 36010304121054676472 | D41: 严金金 | E41: 严金金 | F41: 一手房(转抵押) | G41: 赣（2021）吉安市不动产证明第0017806号 | H41: 140000 | I41: 严金金 | J41: 44337 | K41: 47989 | L41: 万淑红
A42: 41 | B42: 20210528043601030405007 | C42: 36010304121054512525 | D42: 王喜 | E42: 王喜 | F42: 一手房(转抵押) | G42: 赣（2021）吉安市不动产证明第0017802号 | H42: 140000 | I42: 王喜 | J42: 44327 | K42: 47979 | L42: 万淑红
A43: 42 | B43: 20210528043600006304001 | C43: 36010304221050807176 | D43: 王尧海 | E43: 王尧海 陈贱香 | F43: 商贷通 | G43: 赣（2021）吉安市不产证明第0018147号 | H43: 59 | I43: 10 | J43: 44340 | K43: 47262
A44: 43 | B44: 20210531043600006304001 | C44: 3699950Q221050953104 | D44: 伍芳兰 | E44: 杨小敏 伍芬兰 | F44: 网商贷 | G44: 赣（2021）吉安市不产证明第0018262号 | H44: 69 | I44: 10 | J44: 44343 | K44: 47995
A45: 44 | B45: 20210601043600006305001 | C45: 36010316221051058641 | D45: 刘娟 | E45: 刘娟 黄连真 | F45: 综消 | G45: 赣（2021）吉安市不产证明第0018457号 | H45: 48 | I45: 10 | J45: 44347 | K45: 49095
A46: 45 | B46: 20210601043600006304002 | C46: 3601030421050982150 | D46: 袁燕 | E46: 袁燕 吴小建 | F46: 商贷通 | G46: 赣（2021）吉安市不产证明第0018459号 | H46: 49 | I46: 10 | J46: 44343 | K46: 47995
A47: 46 | B47: 20210601043601030404001 | C47: 36010304221050935909 | D47: 吴艳萍 | E47: 吴艳萍 陈旺华 | F47: 政贷通 | G47: 赣（2021）吉安市不产证明第0018460号 | H47: 15 | I47: 2 | J47: 44342 | K47: 44799
A48: 47 | B48: 20210602043600006304001 | C48: 36010316221051062303 | D48: 罗琳萍 | E48: 罗琳萍 | F48: 商贷通 | G48: 赣（2021）吉安市不动产证明第0018674号 | H48: 90 | I48: 10 | J48: 44347 | K48: 47999
A49: 48 | B49: 20210602043600006305003 | C49: 36010304221051081408 | D49: 肖俊材 | E49: 肖俊材 唐莉 | F49: 综消 | G49: 赣（2021）吉安市不动产证明第0018641号 | H49: 45 | I49: 13 | J49: 44347 | K49: 49095
A50: 49 | B50: 20210602043600006304002 | C50: 36010304221051081915 | D50: 刘中华 | E50: 刘中华 吕花蓉 | F50: 极速贷 | G50: 赣（2021）吉安市不动产证明第0018641号 | H50: 67 | I50: 10 | J50: 44347 | K50: 47999
A51: 50 | B51: 20210603043600006304001 | C51: 3601030421061136238 | D51: 胡舵 | E51: 胡舵 邱晔 | F51: 极速贷 | G51: 赣（2021）吉安市不动产证明第0018829号 | H51: 42.6 | I51: 10 | J51: 44348 | K51: 48000
...

Sheet 一手房
A1: 序号 | B1: 封包编号 | C1: 业务合同编号 | D1: 所属楼盘 | E1: 借款人 | F1: 身份证号 | G1: 抵押人 | H1: 权证编号 | I1: 权证类型（贷款种类：一手房) | J1: 抵押金额（万元） | K1: 抵押时间 | L1: 抵押期限 | M1: 联系方式 | N1: 客户经理 | O1: 债务期限（年）
A2: 1 | B2: 20210517043699950Q05001 | C2: 3699950Q116083619779 | D2: 恒大帝景五期（住宅） | E2: 刘圣锋 | F2: 362425198402103213 | G2: 刘圣锋 赵凤霞 | H2: 赣（2021）吉安市不产证明第0009667号 | I2: 抵押登记证明 | J2: 53 | K2: 42585 | L2: 53542 | M2: 18679617121 | N2: 徐求芸 | O2: =DATEDIF(K2,L2,"Y") -> 30
A3: 2 | B3: 20210518043699950Q05001 | C3: 3699950Q116083751487 | D3: 恒大帝景E-4 | E3: 雷婷 | F3: 362425198908091029 | G3: 贺书和 | H3: 赣（2021）吉安市不产证明第0009959号 | I3: 抵押登记证明 | J3: 49 | K3: 42599 | L3: 53556 | M3: 13686400903 | N3: 徐求芸 | O3: =DATEDIF(K3,L3,"Y") -> 30
A4: 3 | B4: 20210518043699950Q05002 | C4: 36010316115090639488 | D4: 恒大帝景三期 | E4: 欧阳春兰 | F4: 362422197502274323 | G4: 欧阳春兰 王文泰 | H4: 赣（2021）吉安市不产证明第0009758号 | I4: 抵押登记证明 | J4: 54 | K4: 42255 | L4: 49560 | M4: 13790092191 | N4: 牛小美 | O4: =DATEDIF(K4,L4,"Y") -> 20
A5: 4 | B5: 20210518043699950Q05017 | C5: 3699950Q116094017795 | D5: 恒大帝景五期（住宅） | E5: 黄松财 | F5: 362422198708166736 | G5: 黄松财 周桂秀 | H5: 赣（2021）吉安市不产证明第0009757号 | I5: 抵押登记证明 | J5: 60 | K5: 42623 | L5: 53580 | M5: 18026529348 | N5: 巫淑芬 | O5: =DATEDIF(K5,L5,"Y") -> 30
A6: 5 | B6: 20210518043699950Q05003 | C6: 3699950Q117025519079 | D6: 恒大帝景E-4 | E6: 王伟伟 | F6: 362422198709095925 | G6: 王伟伟 张小军 | H6: 赣（2021）吉安市不产证明第0009752号 | I6: 抵押登记证明 | J6: 83 | K6: 42775 | L6: 53732 | M6: 13686449042 | N6: 牛小美 | O6: =DATEDIF(K6,L6,"Y") -> 30
A7: 6 | B7: 20210517043699950Q05003 | C7: 36010316115070081532 | D7: 恒大帝景三期 | E7: 龙楚 | F7: 362430198409012032 | G7: 龙楚 欧阳月花 | H7: 赣（2021）吉安市不产证明第0009742号 | I7: 抵押登记证明 | J7: 53 | K7: 42195 | L7: 49500 | M7: 13586329330 | N7: 黄静杰 | O7: =DATEDIF(K7,L7,"Y") -> 20
A8: 7 | B8: 20210518043699950Q05004 | C8: 3699950Q116114644281 | D8: 恒大帝景E-4 | E8: 郑娇英 | F8: 362421198910058644 | G8: 郑娇英 康志勇 | H8: 赣（2021）吉安市不产证明第0009731号 | I8: 抵押登记证明 | J8: 46 | K8: 42691 | L8: 46343 | M8: 13970686763 | N8: 牛小美 | O8: =DATEDIF(K8,L8,"Y") -> 10
A9: 8 | B9: 20210518043699950Q05021 | C9: 3699950Q116052859587 | D9: 恒大帝景五期（住宅） | E9: 李志慧 | F9: 362422199012306213 | G9: 李志慧 罗艳珍 | H9: 赣（2021）吉安市不产证明第0009644号 | I9: 抵押登记证明 | J9: 37 | K9: 42508 | L9: 49813 | M9: 15921287433 | N9: 严姝玲 | O9: =DATEDIF(K9,L9,"Y") -> 20
A10: 9 | B10: 20210518043699950Q05025 | C10: 3699950Q116042576760 | D10: 恒大帝景五期（住宅） | E10: 刘桂平 | F10: 362421197609203836 | G10: 胡慧莲 刘桂平 | H10: 赣（2021）吉安市不产证明第0009574号 | I10: 抵押登记证明 | J10: 68 | K10: 42474 | L10: 51605 | M10: 13627961106 | N10: 严姝玲 | O10: =DATEDIF(K10,L10,"Y") -> 25
A11: 10 | B11: 20210518043699950Q05033 | C11: 3699950Q116094089980 | D11: 恒大帝景五期（住宅） | E11: 高启华 | F11: 36242619760914003X | G11: 高启华 熊清梅 | H11: 赣（2021）吉安市不产证明第0009573号 | I11: 抵押登记证明 | J11: 50 | K11: 42631 | L11: 49936 | M11: 13979611867 | N11: 牛小美 | O11: =DATEDIF(K11,L11,"Y") -> 20
A12: 11 | B12: 20210518043699950Q05027 | C12: 36010330117025495362 | D12: 恒大帝景E-4 | E12: 李臣 | F12: 362401198705182018 | G12: 李臣 胡晓珍 | H12: 赣（2021）吉安市不产证明第0009572号 | I12: 抵押登记证明 | J12: 59 | K12: 42797 | L12: 53754 | M12: 18170461220 | N12: 巫淑芬 | O12: =DATEDIF(K12,L12,"Y") -> 30
A13: 12 | B13: 20210518043699950Q05005 | C13: 36010316114035531900 | D13: 恒大帝景 | E13: 施燕琴 | F13: 362401197705210547 | G13: 施燕琴 彭裕庆 | H13: 赣（2021）吉安市不产证明第0009571号 | I13: 抵押登记证明 | J13: 58 | K13: 41690 | L13: 48995 | M13: 13970460002 | N13: 牛小美 | O13: =DATEDIF(K13,L13,"Y") -> 20
... A50: 49 | B50: 20210517043699950Q05006 | C50: 3699950Q118123740037 | D50: 梦想星城三期 | E50: 张满生 | F50: 362422198109256713 | G50: 张满生 李霞 | H50: 赣（2021）吉安市不产证明第0010283号 | I50: 抵押登记证明 | J50: 60 | K50: 43440 | L50: 52571 | M50: 15107062756 | N50: 黄静杰 | O50: =DATEDIF(K50,L50,"Y") -> 25
A51: 50 | B51: 20210518043699950Q05045 | C51: 3699950Q119066531017 | D51: 梦想星城二期 | E51: 张美丽 | F51: 362422199509222541 | G51: 张美丽 黄平 | H51: 赣（2021）吉安市不产证明第0010286号 | I51: 抵押登记证明 | J51: 60 | K51: 43644 | L51: 2049//6/28 | M51: 18160766377 | N51: 牛小美 | O51: =DATEDIF(K51,L51,"Y") -> #VALUE!
A52: 51 | B52: 20210518043699950Q05047 | C52: 3699950Q119066541971 | D52: 梦想星城三期 | E52: 夏侯庚招 | F52: 362401198707084913 | G52: 夏候庚招 彭琳 | H52: 赣（2021）吉安市不产证明第0010287号 | I52: 抵押登记证明 | J52: 49 | K52: 43645 | L52: 54603 | M52: 18221528982 | N52: 牛小美 | O52: =DATEDIF(K52,L52,"Y") -> 30
A53: 52 | B53: 20210518043699950Q05079 | C53: 3699950Q118050867743 | D53: 梦想星城三期 | E53: 郭志东 | F53: 362421199011263219 | G53: 郭志东 黄端红 | H53: 赣（2021）吉安市不产证明第0010245号 | I53: 抵押登记证明 | J53: 68 | K53: 43203 | L53: 54161 | M53: 18802599497 | N53: 郭元 | O53: =DATEDIF(K53,L53,"Y") -> 30
A54: 53 | B54: 20210518043699950Q05014 | C54: 3699950Q118123625341 | D54: 梦想星城三期 | E54: 肖仁 | F54: 362421198810035314 | G54: 肖仁 刘四妹 | H54: 赣（2021）吉安市不产证明第0010241号 | I54: 抵押登记证明 | J54: 70 | K54: 43466 | L54: 54424 | M54: 15720808994 | N54: 徐求芸 | O54: =DATEDIF(K54,L54,"Y") -> 30
A55: 54 | B55: 20210518043699950Q05049 | C55: 3699950Q119111430364 | D55: 梦想星城三期 | E55: 周小江 | F55: 362429199512125317 | G55: 周小江 朱琳 | H55: 赣（2021）吉安市不产证明第0010244号 | I55: 抵押登记证明 | J55: 54.6 | K55: 43775 | L55: 54733 | M55: 13699851980 | N55: 牛小美 | O55: =DATEDIF(K55,L55,"Y") -> 30
A56: 55 | B56: 20210518043699950Q05050 | C56: 3699950Q118123679491 | D56: 梦想星城三期 | E56: 肖海军 | F56: 362422198701254012 | G56: 肖海军 | H56: 赣（2021）吉安市不产证明第0010246号 | I56: 抵押登记证明 | J56: 63 | K56: 43451 | L56: 54409 | M56: 15813814066 | N56: 牛小美 | O56: =DATEDIF(K56,L56,"Y") -> 30
A57: 56 | B57: 20210518043699950Q05080 | C57: 3699950Q118123624647 | D57: 梦想星城三期 | E57: 吴蔚瑾 | F57: 362426199007172228 | G57: 吴蔚瑾 陈晓洋 | H57: 赣（2021）吉安市不产证明第0010247号 | I57: 抵押登记证明 | J57: 71 | K57: 43433 | L57: 54391 | M57: 18379690890 | N57: 郭元 | O57: =DATEDIF(K57,L57,"Y") -> 30
A58: 57 | B58: 20210518043699950Q05118 | C58: 3699950Q118050847726 | D58: 梦想星城三期 | E58: 吴淑英 | F58: 36242519881224502X | G58: 吴淑英 | H58: 赣（2021）吉安市不产证明第0010248号 | I58: 抵押登记证明 | J58: 67 | K58: 43245 | L58: 54203 | M58: 15384227784 | N58: 钟坤华 | O58: =DATEDIF(K58,L58,"Y") -> 30
A59: 58 | B59: 20210518043699950Q05132 | C59: 3699950Q119045519139 | D59: 梦想星城三期 | E59: 郭三莲 | F59: 362401198411254442 | G59: 郭三莲 胡德耀 | H59: 赣（2021）吉安市不产证明第0010250号 | I59: 抵押登记证明 | J59: 62 | K59: 43579 | L59: 54537 | M59: 13924585230 | N59: 钟坤华 | O59: =DATEDIF(K59,L59,"Y") -> 30
A60: 59 | B60: 20210518043699950Q05052 | C60: 3699950Q118050885042 | D60: 梦想星城三期 | E60: 曹涛生 | F60: 362421199203164151 | G60: 曹涛生 | H60: 赣（2021）吉安市不产证明第0010253号 | I60: 抵押登记证明 | J60: 60 | K60: 43217 | L60: 54175 | M60: 18711370565 | N60: 牛小美 | O60: =DATEDIF(K60,L60,"Y") -> 30
A61: 60 | B61: 20210518043699950Q05054 | C61: 3699950Q118050848364 | D61: 梦想星城三期 | E61: 刘文昌 | F61: 362401199811124932 | G61: 刘文昌 | H61: 赣（2021）吉安市不产证明第0010255号 | I61: 抵押登记证明 | J61: 40 | K61: 43217 | L61: 54175 | M61: 15879632557 | N61: 牛小美 | O61: =DATEDIF(K61,L61,"Y") -> 30
A62: 61 | B62: 20210518043699950Q05057 | C62: 3699950Q119035120371 | D62: 梦想星城三期 | E62: 郭文敢 | F62: 362421199410183515 | G62: 郭文敢 | H62: 赣（2021）吉安市不产证明第0010156号 | I62: 抵押登记证明 | J62: 50 | K62: 43552 | L62: 54510 | M62: 13151593866 | N62: 牛小美 | O62: =DATEDIF(K62,L62,"Y") -> 30
A63: 62 | B63: 20210518043699950Q05059 | C63: 3699950Q118071627805 | D63: 梦想星城三期 | E63: 龙继龙 | F63: 362429199311185313 | G63: 龙继龙 | H63: 赣（2021）吉安市不产证明第0010163号 | I63: 抵押登记证明 | J63: 56 | K63: 43266 | L63: 54224 | M63: 15879098243 | N63: 牛小美 | O63: =DATEDIF(K63,L63,"Y") -> 30
... A259: 258 | B259: 20210630043699950Q05037 | C259: 3699950Q118050880950 | D259: 梦想星城二期 | E259: 廖阳 | F259: 362423199008240537 | G259: 廖阳 周小翠 | H259: 赣（2021）吉安市不产证明第0020913号 | I259: 抵押登记证明 | J259: 73 | K259: 43217 | L259: 54175 | M259: 13128110976 | N259: 严姝玲 | O259: =DATEDIF(K259,L259,"Y") -> 30
A260: 259 | B260: 20210630043699950Q05030 | C260: 3699950Q119045527382 | D260: 梦想星城三期 | E260: 刘秋涛 | F260: 362421198707034110 | G260: 刘秋涛 赖求霞 | H260: 赣（2021）吉安市不产证明第0020914号 | I260: 抵押登记证明 | J260: 63 | K260: 43580 | L260: 2039//4/25 | M260: 13358373661 | N260: 徐求芸 | O260: =DATEDIF(K260,L260,"Y") -> #VALUE!
A261: 260 | B261: 20210630043699950Q05026 | C261: 3699950Q116124985104 | D261: 恒大帝景E-4 | E261: 王峣 | F261: 362401198704231017 | G261: 王峣 郭霞 | H261: 赣（2021）吉安市不产证明第0021265号 | I261: 抵押登记证明 | J261: 59 | K261: 42727 | L261: 53684 | M261: 15114057303 | N261: 黄静杰 | O261: =DATEDIF(K261,L261,"Y") -> 30
A262: 261 | B262: 20210630043699950Q05049 | C262: 36010316114117769262 | D262: 恒大帝景E-5 | E262: 刘忠敏 | F262: 362432198410081011 | G262: 刘忠敏 | H262: 赣（2021）吉安市不产证明第0021261号 | I262: 抵押登记证明 | J262: 54 | K262: 41954 | L262: 52912 | M262: 13713906850 | N262: 钟坤华 | O262: =DATEDIF(K262,L262,"Y") -> 30
A263: 262 | B263: 20210630043699950Q05021 | C263: 36010330116114627280 | D263: 润阳·环湖湾 | E263: 肖鹏翔 | F263: 362428198410121111 | G263: 肖鹏翔 张亚轩 | H263: 赣（2021）吉安市不产证明第0021259号 | I263: 抵押登记证明 | J263: 56 | K263: 42671 | L263: 49976 | M263: 15807963121 | N263: 牛小美 | O263: =DATEDIF(K263,L263,"Y") -> 20
A264: 263 | B264: 20210630043699950Q05005 | C264: 36010330116114478652 | D264: 润阳·环湖湾 | E264: 王俊菁 | F264: 362421198102106839 | G264: 王俊菁 肖秀华 | H264: 赣（2021）吉安市不产证明第0021258号 | I264: 抵押登记证明 | J264: 57 | K264: 42671 | L264: 49976 | M264: 13879677888 | N264: 郭元 | O264: =DATEDIF(K264,L264,"Y") -> 20
A265: 264 | B265: 20210630043699950Q05022 | C265: 36010330116104246530 | D265: 润阳·环湖湾 | E265: 万霖 | F265: 362401198211051018 | G265: 万霖 欧阳春连 | H265: 赣（2021）吉安市不产证明第0021263号 | I265: 抵押登记证明 | J265: 57 | K265: 42634 | L265: 48112 | M265: 15879663100 | N265: 牛小美 | O265: =DATEDIF(K265,L265,"Y") -> 15
A266: 265 | B266: 20210630043699950Q05023 | C266: 3699950Q120129933290 | D266: 吉安时代城（B-15地块） | E266: 曹阳 | F266: 362401199009091539 | G266: 曹阳 | H266: 赣（2021）吉安市不产证明第0021682号 | I266: 预告抵押登记证明 | J266: 35 | K266: 44169 | L266: 51474 | M266: 18510862375 | N266: 牛小美 | O266: =DATEDIF(K266,L266,"Y") -> 20
A267: 266 | B267: 20210630043699950Q05025 | C267: 3699950Q121010856209 | D267: 吉安时代城（B-15地块） | E267: 徐求兰 | F267: 362401199204185223 | G267: 徐求兰 | H267: 赣（2021）吉安市不产证明第0021678号 | I267: 预告抵押登记证明 | J267: 48 | K267: 44203 | L267: 51508 | M267: 13267234576 | N267: 牛小美 | O267: =DATEDIF(K267,L267,"Y") -> 20
A268: 267 | B268: 20210630043699950Q05039 | C268: 36010316115018164388 | D268: 滨江壹号（又称上江界）B区 | E268: 刘爱民 | F268: 362422198008223533 | G268: 刘爱民 唐君 | H268: 赣（2021）吉安市不产证明第0021069号 | I268: 抵押登记证明 | J268: 28 | K268: 41962 | L268: 45615 | M268: 18675718675 | N268: 郭元 | O268: =DATEDIF(K268,L268,"Y") -> 10
A269: 268 | B269: 20210712043601031605001 | C269: 36010239116073368436 | D269: 凯旋中央城北区 | E269: 杨言安 | F269: 36242119890311533X | G269: 滕慧敏 杨言安 | H269: 赣（2021）吉安市不动产证明第0022042号 | I269: 抵押登记证明 | J269: 46 | K269: 42549 | L269: 48027 | M269: 15364926048 | N269: 徐求芸 | O269: =DATEDIF(K269,L269,"Y") -> 15
A270: 269 | B270: 20210716043699950Q05003 | C270: 36010330116063004641 | D270: 凯旋世纪 | E270: 刘文萍 | F270: 362421198905011120 | G270: 俞卫平 刘文萍 | H270: 赣（2021）吉安市不动产证明第0022524号 | I270: 抵押登记证明 | J270: 29 | K270: 42510 | L270: 47988 | M270: 18070568401 | N270: 黄静杰 | O270: =DATEDIF(K270,L270,"Y") -> 15
A271: 270 | B271: 20210720043601031605002 | C271: 36010239116052807462 | D271: 凯旋世纪 | E271: 刘梦麒 | F271: 362401196211191011 | G271: 周丽萍 刘梦麒 | H271: 赣（2021）吉安市不动产证明第0023342号 | I271: 抵押登记证明 | J271: 44.5 | K271: 42500 | L271: 46152 | M271: 13807969359 | N271: 郭元 | O271: =DATEDIF(K271,L271,"Y") -> 10
...

Sheet 车贷
A1: 序号 | B1: 封包号 | C1: 业务合同编号 | D1: 借款人 | E1: 抵押人 | F1: 贷种 | G1: 机动车登记编号 | H1: 机动车登记证书编号 | I1: 抵押金额（万元） | J1: 抵押登记日期 | K1: 借款期限 | L1: 客户经理 | M1: 工号 | N1: 放款日期 | O1: 车辆品牌 | P1: 登记日期
A2: 818 | B2: cd000000000000000000818 | C2: 36010304121119788040 | D2: 郭嘉文 | E2: 郭嘉文 | F2: 个人汽车消费贷款（合作平台） | G2: 赣DD22215 | H2: 360016733117 | I2: 10 | J2: 44532 | K2: 3 | L2: 赖丽君
A3: 819 | B3: cd000000000000000000819 | C3: 36010304121119803088 | D3: 阮文捷 | E3: 阮文捷 | F3: 个人汽车消费贷款（合作平台） | G3: 赣DR4656 | H3: 360016733109 | I3: 10 | J3: 44538 | K3: 3 | L3: 赖丽君
A4: 820 | B4: cd000000000000000000820 | C4: 36010304121120345719 | D4: 谢廖莎 | E4: 谢廖莎 | F4: 个人汽车消费贷款（合作平台） | G4: 赣D1816W | H4: 360014593842 | I4: 13 | J4: 44545 | K4: 5 | L4: 万淑红
A5: 821 | B5: cd000000000000000000821 | C5: 36010304121120828033 | D5: 肖汉英 | E5: 肖汉英 | F5: 个人汽车消费贷款（合作平台） | G5: 赣DCJ532 | H5: 360017464571 | I5: 15.4 | J5: 44583 | K5: 3 | L5: 万淑红
A6: 822 | B6: cd000000000000000000822 | C6: 36010304122033428267 | D6: 李深渊 | E6: 李深渊 | F6: 个人汽车消费贷款（合作平台） | G6: 赣DAB752 | H6: 360016757441 | I6: 10 | J6: 44648 | K6: 5 | L6: 万淑红
A7: 823 | B7: cd000000000000000000823 | C7: 36010278122044078424 | D7: 曾金华 | E7: 曾金华 | F7: 个人汽车消费贷款（快速） | G7: 赣D22V00 | H7: 360018810363 | I7: 7 | J7: 44664 | K7: 3 | L7: 谢文青
A8: 824 | B8: cd000000000000000000824 | C8: 2022041280002431 | D8: 曾卫明 | E8: 曾卫明 | F8: 汽车分期 | G8: 赣D676A8 | H8: 360016785898 | I8: 16 | J8: 44673 | K8: 5 | L8: 王婷
A9: 825 | B9: cd000000000000000000825 | C9: 2022042680001466 | D9: 范芳云 | E9: 范芳云 | F9: 汽车分期 | G9: 赣DQ9655 | H9: 360018864876 | I9: 10 | J9: 44680 | K9: 3 | L9: 郭玲风
A10: 826 | B10: cd000000000000000000826 | C10: 2022042580001203 | D10: 刘新美 | E10: 刘新美 | F10: 汽车分期 | G10: 赣DFD802 | H10: 360018864890 | I10: 25 | J10: 44679 | K10: 5 | L10: 郭玲风
A11: 827 | B11: cd000000000000000000827 | C11: 2022042580003264 | D11: 欧阳军军 | E11: 欧阳军军 | F11: 汽车分期 | G11: 赣D22U51 | H11: 360018864883 | I11: 33 | J11: 44679 | K11: 5 | L11: 郭玲风
A12: 828 | B12: cd000000000000000000828 | C12: 2022042580001570 | D12: 尹奕花 | E12: 尹奕花 | F12: 汽车分期 | G12: 赣DGB711 | H12: 360018864873 | I12: 20 | J12: 44680 | K12: 5 | L12: 郭玲风
A13: 829 | B13: cd000000000000000000829 | C13: 2022050780001519 | D13: 颜运林 | E13: 颜运林 | F13: 汽车分期 | G13: 赣DHT313 | H13: 360018863228 | I13: 14.9 | J13: 44690 | K13: 5 | L13: 谢文青
... A155: 971 | B155: cd000000000000000000971 | C155: 2022100780000805 | D155: 肖慧玲 | E155: 肖慧玲 | F155: 汽车分期 | G155: 赣D05A83 | H155: 360019439377 | I155: 30 | J155: 44845 | K155: 5 | L155: 黄艳
A156: 972 | B156: cd000000000000000000972 | C156: 2022101080001139 | D156: 欧阳燕虹 | E156: 欧阳燕虹 | F156: 汽车分期 | G156: 赣DEP373 | H156: 360018097752 | I156: 20.9 | J156: 44848 | K156: 5 | L156: 黄艳 | M156: 20080117330 | N156: 44847 | O156: 梅赛德斯-奔驰牌 | P156: 44848
A157: 973 | B157: cd000000000000000000973 | C157: 2022100980001074 | D157: 王嘉敏 | E157: 王嘉敏 | F157: 汽车分期 | G157: 赣D8547DS | H157: 360018816499 | I157: 20 | J157: 44848 | K157: 5 | L157: 黄艳 | M157: 20080117330 | N157: 44845 | O157: 梅赛德斯-奔驰牌 | P157: 44848
A158: 974 | B158: cd000000000000000000974 | C158: 2022100880000966 | D158: 王清和 | E158: 王清和 | F158: 汽车分期 | G158: 赣DEB968 | H158: 360018816497 | I158: 20 | J158: 44848 | K158: 5 | L158: 黄艳 | M158: 20080117330 | N158: 44847 | O158: 梅赛德斯-奔驰牌 | P158: 44848
A159: 975 | B159: cd000000000000000000975 | C159: 2022101280002257 | D159: 杨艺芳 | E159: 杨艺芳 | F159: 汽车分期 | G159: 赣DDA603 | H159: 360018097751 | I159: 15 | J159: 44848 | K159: 5 | L159: 黄艳 | M159: 20080117330 | N159: 44847 | O159: 梅赛德斯-奔驰牌 | P159: 44848
A160: 976 | B160: cd000000000000000000976 | C160: 2022100880000911 | D160: 曾新华 | E160: 曾新华 | F160: 汽车分期 | G160: 赣DBZ357 | H160: 360018097771 | I160: 20 | J160: 44851 | K160: 5 | L160: 黄艳 | M160: 20080117330 | N160: 44851 | O160: 梅赛德斯-奔驰牌 | P160: 44851
A161: 977 | B161: cd000000000000000000977 | C161: 2022101380000961 | D161: 林贵鸿 | E161: 林贵鸿 | F161: 汽车分期 | G161: 赣DGR310 | H161: 360018097772 | I161: 36 | J161: 44851 | K161: 5 | L161: 黄艳 | M161: 20080117330 | N161: 44851 | O161: 梅赛德斯-奔驰牌 | P161: 44851
A162: 978 | B162: cd000000000000000000978 | C162: 2022101780000674 | D162: 卢心月 | E162: 卢心月 | F162: 汽车分期 | G162: 赣DDQ516 | H162: 360018097788 | I162: 23 | J162: 44854 | K162: 5 | L162: 黄艳 | M162: 20080117330 | N162: 44852 | O162: 梅赛德斯-奔驰牌 | P162: 44854
A163: 979 | B163: cd000000000000000000979 | C163: 2022081280002921 | D163: 匡建华 | E163: 匡建华 | F163: 汽车分期 | G163: 赣DF87139 | H163: 360018858193 | I163: 20 | J163: 44844 | K163: 4 | L163: 胡涛 | M163: 20090703750 | N163: 44844 | O163: 赛力斯牌 | P163: 44844
A164: 980 | B164: cd000000000000000000980 | C164: 2022102380000929 | D164: 缪雪萍 | E164: 缪雪萍 | F164: 汽车分期 | G164: 赣DAU997 | H164: 360018097722 | I164: 25 | J164: 44860 | K164: 5 | L164: 黄艳 | M164: 20080117330 | N164: 44859 | O164: 梅赛德斯-奔驰牌 | P164: 44860
A165: 981 | B165: cd000000000000000000981 | C165: 2022082280001690 | D165: 王振 | E165: 王振 | F165: 汽车分期 | G165: 赣D59556 | H165: 360018816450 | I165: 25 | J165: 44805 | K165: 3 | L165: 黄艳
A166: 982 | B166: cd000000000000000000982 | C166: 36010278122100061670 | D166: 付雪兵 | E166: 付雪兵 | F166: 个人汽车消费贷款（快速） | G166: 赣D01Y20 | H166: 360018880190 | I166: 8 | J166: 44859 | K166: 5 | L166: 王婷 | M166: 20111138170 | N166: 44860 | O166: 本田牌 | P166: 44859
A167: 983 | B167: cd000000000000000000983 | C167: 2022102580000765 | D167: 刘云明 | E167: 刘云明 | F167: 汽车分期 | G167: 赣D903V6 | H167: 360018097729 | I167: 31 | J167: 44862 | K167: 5 | L167: 黄艳 | M167: 20080117330 | N167: 44860 | O167: 梅赛德斯-奔驰牌 | P167: 44862
A168: 984 | B168: cd000000000000000000984 | C168: 2022092980002861 | D168: 郭庭裕 | E168: 郭庭裕 | F168: 汽车分期 | G168: 赣D5559K | H168: 360018078446 | I168: 15 | J168: 44843 | K168: 5 | L168: 李俊 | M168: 20200856460 | N168: 44842 | O168: 凯迪拉克牌 | P168: 44843
A169: 985 | B169: cd000000000000000000985 | C169: 2022103080000882 | D169: 罗小勇 | E169: 罗小勇 | F169: 汽车分期 | G169: 赣D3E996 | H169: 360018097854 | I169: 20 | J169: 44867 | K169: 5 | L169: 黄艳 | M169: 20080117330 | N169: 44867 | O169: 梅赛德斯-奔驰牌 | P169: 44867
A170: 986 | B170: cd000000000000000000986 | C170: 2022103080000434 | D170: 吴亮明 | E170: 吴亮明 | F170: 汽车分期 | G170: 赣DGB808 | H170: 360016764429 | I170: 18 | J170: 44867 | K170: 3 | L170: 梅洁 | M170: 20090741840 | N170: 44866 | O170: 梅赛德斯-奔驰牌 | P170: 44867
A171: 987 | B171: cd000000000000000000987 | C171: 2022102880001529 | D171: 谢玮 | E171: 谢玮 | F171: 汽车分期 | G171: 赣D2518Z | H171: 360018097862 | I171: 20 | J171: 44868 | K171: 3 | L171: 黄艳 | M171: 20080117330 | N171: 44866 | O171: 梅赛德斯-奔驰牌 | P171: 44868
A172: 988 | B172: cd000000000000000000988 | C172: 2022103080000365 | D172: 杨坤 | E172: 杨坤 | F172: 汽车分期 | G172: 赣D8232Z | H172: 360018097861 | I172: 15 | J172: 44868 | K172: 5 | L172: 梅洁 | M172: 20090741840 | N172: 44867 | O172: 梅赛德斯-奔驰牌 | P172: 44868
A173: 989 | B173: cd000000000000000000989 | C173: 2022103080000273 | D173: 蒋邦纲 | E173: 蒋邦纲 | F173: 汽车分期 | G173: 赣DGB126 | H173: 360018097570 | I173: 24.8 | J173: 44872 | K173: 5 | L173: 梅洁 | M173: 20090741840 | N173: 44867 | O173: 梅赛德斯-奔驰牌 | P173: 44872
A174: 990 | B174: cd000000000000000000990 | C174: 2022102580003553 | D174: 李艳 | E174: 李艳 | F174: 汽车分期 | G174: 赣D68S30 | H174: 360018097867 | I174: 30 | J174: 44872 | K174: 5 | L174: 黄艳 | M174: 20080117330 | N174: 44862 | O174: 梅赛德斯-奔驰牌 | P174: 44872
A175: 991 | B175: cd000000000000000000991 | C175: 2022110180001773 | D175: 喻小兰 | E175: 喻小兰 | F175: 汽车分期 | G175: 赣DEJ638 | H175: 360018097567 | I175: 17.5 | J175: 44869 | K175: 5 | L175: 黄艳 | M175: 20080117330 | N175: 44869 | O175: 梅赛德斯-奔驰牌 | P175: 44869
A176: 992 | B176: cd000000000000000000992 | C176: 2022102580003006 | D176: 朱芬芬 | E176: 朱芬芬 | F176: 汽车分期 | G176: 赣DGT822 | H176: 360018097863 | I176: 23 | J176: 44868 | K176: 5 | L176: 黄艳 | M176: 20080117330 | N176: 44862 | O176: 梅赛德斯-奔驰牌 | P176: 44868
A177: 993 | B177: cd000000000000000000993 | C177: 2022071280001411 | D177: 黄波 | E177: 黄波 | F177: 汽车分期 | G177: 赣H9K730 | H177: 360017516505 | I177: 15 | J177: 44875 | K177: 5 | L177: 谢文青 | M177: 20110321710 | N177: 44756 | O177: 凯迪拉克牌 | P177: 44781
... A198: 1014 | B198: cd000000000000000001014 | C198: 2022112380001524 | D198: 杨美英 | E198: 杨美英 | F198: 汽车分期 | G198: 赣D5235M | H198: 360018097541 | I198: 30 | J198: 44890 | K198: 5 | L198: 严利 | M198: 20210843420 | N198: 44889 | O198: 梅赛德斯-奔驰牌 | P198: 44890
A199: 1015 | B199: cd000000000000000001015 | C199: 2022110780001845 | D199: 罗小年 | E199: 罗小年 | F199: 汽车分期 | G199: 赣DDH520 | H199: 360018853148 | I199: 12 | J199: 44895 | K199: 5 | L199: 李俊 | M199: 20200856460 | N199: 44880 | O199: 凯迪拉克牌 | P199: 44895 | Q199: 20230222FQ3600006301001
A200: 1016 | B200: cd000000000000000001016 | C200: 2022113080001308 | D200: 李江娅 | E200: 李江娅 | F200: 汽车分期 | G200: 赣D55672 | H200: 360018097849 | I200: 25 | J200: 44901 | K200: 5 | L200: 严利 | M200: 20210843420 | N200: 44901 | O200: 梅赛德斯-奔驰牌 | P200: 44901
A201: 1017 | B201: cd000000000000000001017 | C201: 2022112480002205 | D201: 王丽娟 | E201: 王丽娟 | F201: 汽车分期 | G201: 赣DHY890 | H201: 360018097836 | I201: 15.3 | J201: 44896 | K201: 5 | L201: 严利 | M201: 20210843420 | N201: 44894 | O201: 梅赛德斯-奔驰牌 | P201: 44895
...

Sheet 船舶
A1: 序号 | B1: 封包号 | C1: 业务合同编号 | D1: 借款人 | E1: 抵押人 | F1: 贷种 | G1: 船名 | H1: 船舶识别号 | I1: 抵押权登记号码 | J1: 抵押金额（万元） | K1: 抵押日期 | L1: 客户经理 | M1: 江西省吉安市地方海事局
A2: 1 | B2: 24012316043600006304001 | C2: 36010304224011341999 | D2: 龚冲冲 | E2: 江西赣鸿航运有限公司 | F2: 极速贷抵押额度 | G2: 赣鸿99 | H2: CN20079391186 | I2: DY3502240002 | J2: 50 | K2: 45314 | L2: 邓卫民

Sheet 汽车分期
A1: 客户姓名 | B1: 放款日期 | C1: 联系电话 | D1: 分享卡号 | E1: 归属分支行 | F1: 车辆品牌 | G1: 车辆类型1 | H1: 合作方式2 | I1: 车辆权证编码 | J1: 上牌地 | K1: 车辆产权登记日期 | L1: 抵押登记日期 | M1: 抵押权证入库日期 | N1: 抵押权证出库日期 | O1: 业务合同编号 | P1: 机动车登记编号 | Q1: 机动车登记证书编号 | R1: 抵押金额（万元） | S1: 借款期限 | T1: 客户经理 | U1: 备注 | V1: 押品编号
A2: 曾卫明 | B2: 44665 | C2: 13879636025 | D2: 6228110084348796 | E2: 吉安市青原大道支行 | F2: 凯迪拉克 | G2: 一手自用车 | H2: 直客式 | I2: cd000000000000000000824 | J2: 吉安市 | K2: 44673 | L2: 44673 | M2: 44680 | O2: 2022041280002431 | P2: 赣D676A8 | Q2: 360016785898 | R2: 16 | S2: 5 | T2: 王婷 | U2: 240700 | V2: YP360000632302230232
A3: 范芳云 | B3: 44678 | C3: 13367964455 | D3: 6228110084364314 | E3: 吉安市分行 | F3: 梅赛德斯-奔驰牌 | G3: 一手自用车 | H3: 直客式 | I3: cd000000000000000000825 | J3: 吉安市 | K3: 44680 | L3: 44680 | M3: 44691 | O3: 2022042680001466 | P3: 赣DQ9655 | Q3: 360018864876 | R3: 10 | S3: 3 | T3: 郭玲风 | V3: YP360000632302230231
A4: 刘新美 | B4: 44678 | C4: 19169726378 | D4: 6228110084364256 | E4: 吉安市分行 | F4: 梅赛德斯-奔驰牌 | G4: 一手自用车 | H4: 直客式 | I4: cd000000000000000000826 | J4: 吉安市 | K4: 44679 | L4: 44679 | M4: 44691 | O4: 2022042580001203 | P4: 赣DFD802 | Q4: 360018864890 | R4: 25 | S4: 5 | T4: 郭玲风 | V4: YP360000632302230230
A5: 欧阳军军 | B5: 44678 | C5: 13576888887 | D5: 6228110084364330 | E5: 吉安市分行 | F5: 梅赛德斯-奔驰牌 | G5: 一手自用车 | H5: 直客式 | I5: cd000000000000000000827 | J5: 吉安市 | K5: 44679 | L5: 44679 | M5: 44691 | O5: 2022042580003264 | P5: 赣D22U51 | Q5: 360018864883 | R5: 33 | S5: 5 | T5: 郭玲风 | V5: YP360000632302230229
A6: 尹奕花 | B6: 44679 | C6: 15779619088 | D6: 6228110084367051 | E6: 吉安市分行 | F6: 梅赛德斯-奔驰牌 | G6: 一手自用车 | H6: 直客式 | I6: cd000000000000000000828 | J6: 吉安市 | K6: 44680 | L6: 44680 | M6: 44691 | O6: 2022042580001570 | P6: 赣DGB711 | Q6: 360018864873 | R6: 20 | S6: 5 | T6: 郭玲风 | V6: YP360000632302230228
A7: 颜运林 | B7: 44690 | C7: 15521824043 | D7: 6228110084375484 | E7: 吉安市青原大道支行 | F7: 凯迪拉克 | G7: 一手自用车 | H7: 直客式 | I7: cd000000000000000000829 | J7: 吉安市 | K7: 44690 | L7: 44680 | M7: 44697 | O7: 2022050780001519 | P7: 赣DHT313 | Q7: 360018863228 | R7: 14.9 | S7: 5 | T7: 谢文青 | V7: YP360000632302230227
A8: 赖章红 | B8: 44686 | C8: 13979696853 | D8: 6228110084366780 | E8: 吉安市分行 | F8: 凯迪拉克 | G8: 一手自用车 | H8: 直客式 | I8: cd000000000000000000830 | J8: 吉安市 | K8: 44692 | L8: 44692 | M8: 44697 | O8: 2022042980003295 | P8: 赣DAG326 | Q8: 360016781899 | R8: 22 | S8: 5 | T8: 郭玲风 | V8: YP360000632302230226
A9: 项海珍 | B9: 44693 | C9: 15079668829 | D9: 6228110084380674 | E9: 吉安市分行 | F9: 梅赛德斯-奔驰牌 | G9: 一手自用车 | H9: 直客式 | I9: cd000000000000000000831 | J9: 吉安市 | K9: 44694 | L9: 44694 | M9: 44697 | O9: 2022051080001878 | P9: 赣DIQ388 | Q9: 360018864732 | R9: 24 | S9: 3 | T9: 郭玲风 | V9: YP360000632302230225
A10: 胡阳斌 | B10: 44700 | C10: 18160763149 | D10: 6228110084388800 | E10: 吉安市青原大道支行 | F10: 凯迪拉克 | G10: 一手自用车 | H10: 直客式 | I10: cd000000000000000000832 | J10: 吉安市 | K10: 44699 | L10: 44699 | M10: 44706 | N10: 44775 | O10: 2022051580001032 | P10: 赣DHQ283 | Q10: 360018863277 | R10: 19 | S10: 5 | T10: 谢文青 | V10: YP360000632302230224
A11: 杨敬云 | B11: 44705 | C11: 13397066777 | D11: 6228110084400647 | E11: 吉安市分行 | F11: 梅赛德斯-奔驰牌 | G11: 一手自用车 | H11: 直客式 | I11: cd000000000000000000833 | J11: 吉安市 | K11: 44706 | L11: 44706 | M11: 44708 | O11: 2022051880002193 | P11: 赣DBH607 | Q11: 360018842141 | R11: 47 | S11: 5 | T11: 郭玲风 | V11: YP360000632302230223
A12: 罗晓武 | B12: 44708 | C12: 18507967797 | D12: 6228110084414044 | E12: 吉安市分行 | F12: 梅赛德斯-奔驰牌 | G12: 一手自用车 | H12: 直客式 | I12: cd000000000000000000834 | J12: 吉安市 | K12: 44712 | L12: 44712 | M12: 44714 | O12: 2022052480002606 | P12: 赣DF5096 | Q12: 360018057395 | R12: 28 | S12: 5 | T12: 郭玲风 | V12: YP360000632302230222
A13: 曹江湖 | B13: 44713 | C13: 13237965999 | D13: 6228110084418078 | E13: 吉安市分行 | F13: 梅赛德斯-奔驰牌 | G13: 一手自用车 | H13: 直客式 | I13: cd000000000000000000835 | J13: 吉安市 | K13: 44714 | L13: 44714 | M13: 44722 | O13: 2022052680003454 | P13: 赣DFQ557 | Q13: 360018842159 | R13: 70 | S13: 5 | T13: 梅洁 | V13: YP360000632302230221
A14: 刘金秀 | B14: 44718 | C14: 15107910552 | D14: 6228110084421908 | E14: 吉安市分行 | F14: 梅赛德斯-奔驰牌 | G14: 一手自用车 | H14: 直客式 | I14: cd000000000000000000836 | J14: 吉安市 | K14: 44719 | L14: 44719 | M14: 44722 | O14: 2022060180002955 | P14: 赣DCG225 | Q14: 360018057160 | R14: 20 | S14: 4 | T14: 梅洁 | V14: YP360000632302230220
A15: 夏候耀鹏 | B15: 44720 | C15: 13033297463 | D15: 6228110084434620 | E15: 吉安市青原大道支行 | F15: 凯迪拉克 | G15: 一手自用车 | H15: 直客式 | I15: cd000000000000000000837 | J15: 吉安市 | K15: 44720 | L15: 44720 | M15: 44729 | O15: 2022060780002506 | P15: 赣D7IY77 | Q15: 360018858671 | R15: 10 | S15: 3 | T15: 谢文青 | V15: YP360000632302230217
A16: 张连文 | B16: 44712 | C16: 18321635592 | D16: 6228110084422195 | E16: 吉安市青原大道支行 | F16: 凯迪拉克 | G16: 一手自用车 | H16: 直客式 | I16: cd000000000000000000838 | J16: 吉安市 | K16: 44713 | L16: 44713 | M16: 44729 | O16: 2022052780004503 | P16: 赣DDA652 | Q16: 360018858782 | R16: 10 | S16: 5 | T16: 王婷 | V16: YP360000632302230209
A17: 杨玲 | B17: 44719 | C17: 15970232023 | D17: 6228110084407311 | E17: 吉安市分行 | F17: 梅赛德斯-奔驰牌 | G17: 一手自用车 | H17: 直客式 | I17: cd000000000000000000839 | J17: 吉安市 | K17: 44719 | L17: 44719 | M17: 44729 | O17: 2022052380003438 | P17: 赣DFY367 | Q17: 360018057423 | R17: 22.5 | S17: 5 | T17: 郭玲风 | V17: YP360000632302230219
A18: 张飘兵 | B18: 44722 | C18: 15907960601 | D18: 6228110084441385 | E18: 吉安市分行 | F18: 梅赛德斯-奔驰牌 | G18: 一手自用车 | H18: 直客式 | I18: cd000000000000000000840 | J18: 吉安市 | K18: 44725 | L18: 44725 | M18: 44729 | O18: 2022060480000553 | P18: 赣DM1360 | Q18: 360018859242 | R18: 50 | S18: 4 | T18: 梅洁 | V18: YP360000632302230218
A19: 曾钦湖 | B19: 44722 | C19: 19907993218 | D19: 6228110084447200 | E19: 吉安市城北支行 | F19: 凯迪拉克 | G19: 一手自用车 | H19: 直客式 | I19: cd000000000000000000841 | J19: 萍乡市 | K19: 44726 | L19: 44726 | M19: 44739 | O19: 2022060980005184 | P19: 赣JE0307 | Q19: 360017035866 | R19: 15 | S19: 3 | T19: 周颖 | V19: YP360000632302230215
A20: 刘云甫 | B20: 44722 | C20: 13979628258 | D20: 6228110084441617 | E20: 吉安市分行 | F20: 梅赛德斯-奔驰牌 | G20: 一手自用车 | H20: 直客式 | I20: cd000000000000000000842 | J20: 吉安市 | K20: 44727 | L20: 44727 | M20: 44739 | O20: 2022060780002698 | P20: 赣D16Z89 | Q20: 360018057308 | R20: 30 | S20: 5 | T20: 梅洁 | V20: YP360000632302230216
A21: 段德泓 | B21: 44726 | C21: 18870659464 | D21: 6228110084449925 | E21: 吉安市城北支行 | F21: 奥迪牌 | G21: 一手自用车 | H21: 直客式 | I21: cd000000000000000000843 | J21: 吉安市 | K21: 44727 | L21: 44727 | M21: 44739 | O21: 2022061380002260 | P21: 赣D01S70 | Q21: 360018072842 | R21: 15 | S21: 3 | T21: 徐求芸 | V21: YP360000632302230213
A22: 刘益平 | B22: 44726 | C22: 13929052766 | D22: 6228110084444587 | E22: 吉安市城北支行 | F22: 奥迪牌 | G22: 一手自用车 | H22: 直客式 | I22: cd000000000000000000844 | J22: 吉安市 | K22: 44727 | L22: 44727 | M22: 44739 | O22: 2022061080003441 | P22: 赣DFY922 | Q22: 360018072833 | R22: 14.98 | S22: 3 | T22: 徐求芸 | V22: YP360000632302230214
A23: 戴平 | B23: 44726 | C23: 13879631787 | D23: 6228110084454404 | E23: 吉安市青原大道支行 | F23: 凯迪拉克 | G23: 一手自用车 | H23: 直客式 | I23: cd000000000000000000845 | J23: 吉安市 | K23: 44727 | L23: 44727 | M23: 44739 | O23: 2022061380001757 | P23: 赣D96V15 | Q23: 360018858504 | R23: 10 | S23: 5 | T23: 谢文青 | V23: YP360000632302230212
A24: 刘舟 | B24: 44727 | C24: 15170206904 | D24: 6228110084450857 | E24: 吉安市青原大道支行 | F24: 凯迪拉克 | G24: 一手自用车 | H24: 直客式 | I24: cd000000000000000000846 | J24: 吉安市 | K24: 44727 | L24: 44727 | M24: 44739 | O24: 2022061280000375 | P24: 赣DFM638 | Q24: 360018858886 | R24: 15 | S24: 5 | T24: 谢文青 | V24: YP360000632302230211
A25: 周子燕 | B25: 44720 | C25: 13979641188 | D25: 6228110084434760 | E25: 吉安市青原大道支行 | F25: 沃尔沃 | G25: 一手自用车 | H25: 直客式 | I25: cd000000000000000000847 | J25: 吉安市 | K25: 44727 | L25: 44727 | M25: 44739 | O25: 2022060780003220 | P25: 赣D3551W | Q25: 360016712168 | R25: 17 | S25: 3 | T25: 王婷 | V25: YP360000632302230210
A26: 姚亮 | B26: 44732 | C26: 18107061010 | D26: 6228110084469204 | E26: 吉安市青原大道支行 | F26: 丰田牌 | G26: 一手自用车 | H26: 直客式 | I26: cd000000000000000000848 | J26: 吉安市 | K26: 44732 | L26: 44732 | M26: 44739 | O26: 2022061780003464 | P26: 赣D5207M | Q26: 360018057440 | R26: 15 | S26: 3 | T26: 谢文青 | V26: YP360000632302230207
A27: 冯秋根 | B27: 44727 | C27: 13879654628 | D27: 6228110084459015 | E27: 吉安市青原大道支行 | F27: 凯迪拉克 | G27: 一手自用车 | H27: 直客式 | I27: cd000000000000000000849 | J27: 吉安市 | K27: 44728 | L27: 44728 | M27: 44739 | O27: 2022061380001705 | P27: 赣DE1888 | Q27: 360018858878 | R27: 27 | S27: 5 | T27: 谢文青 | V27: YP360000632302230206
... A51: 肖少敏 | B51: 44727 | C51: 13907961276 | D51: 6228110084455492 | E51: 吉安市城北支行 | F51: 奥迪牌 | G51: 一手自用车 | H51: 直客式 | I51: cd000000000000000000873 | J51: 吉安市 | K51: 44736 | L51: 44736 | M51: 44750 | O51: 2022061480001852 | P51: 赣D1Q888 | Q51: 360018072922 | R51: 15 | S51: 3 | T51: 周颖 | V51: YP360000632302230187
A52: 黄丽萍 | B52: 44746 | D52: 622811******5022 | E52: 吉安市分行 | F52: 梅赛德斯-奔驰牌 | G52: 一手自用车 | H52: 直客式 | I52: cd000000000000000000874 | J52: 吉安市 | K52: 44746 | L52: 44746 | M52: 44750 | O52: 2022062980002904 | P52: 赣DGF877 | Q52: 360018057296 | R52: 35.8 | S52: 5 | T52: 梅洁 | V52: YP360000632302230183
A53: 罗亮 | B53: 44742 | C53: 15179629668 | D53: 6228110084503481 | E53: 吉安市分行 | F53: 梅赛德斯-奔驰牌 | G53: 一手自用车 | H53: 直客式 | I53: cd000000000000000000875 | J53: 吉安市 | K53: 44746 | L53: 44746 | M53: 44750 | O53: 2022062880003946 | P53: 赣DL8800 | Q53: 360018057058 | R53: 35 | S53: 5 | T53: 梅洁 | V53: YP360000632302230182
A54: 涂林荣 | B54: 44742 | C54: 13970672798 | D54: 6228110084501899 | E54: 吉安市分行 | F54: 梅赛德斯-奔驰牌 | G54: 一手自用车 | H54: 直客式 | I54: cd000000000000000000876 | J54: 吉安市 | K54: 44746 | L54: 44746 | M54: 44750 | O54: 2022062980001609 | P54: 赣DDV772 | Q54: 360018057064 | R54: 24.58 | S54: 5 | T54: 梅洁 | V54: YP360000632207080001
A55: 肖辉 | B55: 44741 | C55: 13600189334 | D55: 6228110084505163 | E55: 吉安市青原大道支行 | F55: 凯迪拉克 | G55: 一手自用车 | H55: 直客式 | I55: cd000000000000000000877 | J55: 吉安市 | K55: 44741 | L55: 44741 | M55: 44754 | O55: 2022062980000539 | P55: 赣DEC011 | Q55: 360018072394 | R55: 15 | S55: 5 | T55: 谢文青 | V55: YP360000632302230181
A56: 颜轶群 | B56: 44740 | C56: 18779619192 | D56: 6228110084499300 | E56: 吉安市青原大道支行 | F56: 领克 | G56: 一手自用车 | H56: 直客式 | I56: cd000000000000000000878 | J56: 吉安市 | K56: 44741 | L56: 44741 | M56: 44754 | O56: 2022062880001586 | P56: 赣DNG965 | Q56: 360018873720 | R56: 15 | S56: 5 | T56: 谢文青 | V56: YP360000632302230180
A57: 杨舟 | B57: 44742 | C57: 15949689119 | D57: 6228110084471572 | E57: 吉安市青原大道支行 | F57: 凯迪拉克 | G57: 一手自用车 | H57: 直客式 | I57: cd000000000000000000879 | J57: 吉安市 | K57: 44746 | L57: 44746 | M57: 44754 | O57: 2022062080002875 | P57: 赣DHX298 | Q57: 360018866266 | R57: 15 | S57: 5 | T57: 谢文青 | V57: YP360000632302230179
A58: 刘金明 | B58: 44746 | D58: 622811******8435 | E58: 吉安市青原大道支行 | F58: 凯迪拉克 | G58: 一手自用车 | H58: 直客式 | I58: cd000000000000000000880 | J58: 吉安市 | K58: 44746 | L58: 44746 | M58: 44754 | O58: 2022062780001742 | P58: 赣DHP001 | Q58: 360018072464 | R58: 20 | S58: 5 | T58: 谢文青 | V58: YP360000632302230178
A59: 肖俊 | B59: 44741 | D59: 622811******5163 | E59: 吉安市青原大道支行 | F59: 凯迪拉克 | G59: 一手自用车 | H59: 直客式 | I59: cd000000000000000000881 | J59: 吉安市 | K59: 44742 | L59: 44742 | M59: 44754 | O59: 2022062980000539 | P59: 赣DEH239 | Q59: 360018835997 | R59: 15 | S59: 5 | T59: 谢文青 | V59: YP360000632302230181
A60: 易莉 | B60: 44741 | C60: 13319343334 | D60: 6228110084503200 | E60: 吉安市青原大道支行 | F60: 凯迪拉克 | G60: 一手自用车 | H60: 直客式 | I60: cd000000000000000000882 | J60: 宜春市 | K60: 44748 | L60: 44748 | M60: 44757 | O60: 2022062880002023 | P60: 赣CPA167 | Q60: 360014956976 | R60: 15 | S60: 5 | T60: 谢文青 | V60: YP360000632302230164
A61: 黄文豪 | B61: 44753 | D61: 622811******8893 | E61: 吉安市分行 | F61: 梅赛德斯-奔驰牌 | G61: 一手自用车 | H61: 直客式 | I61: cd000000000000000000883 | J61: 吉安市 | K61: 44753 | L61: 44753 | M61: 44757 | O61: 2022070780002566 | P61: 赣D9852N | Q61: 360018057328 | R61: 10 | S61: 3 | T61: 梅洁 | V61: YP360000632302230175
A62: 刘富根 | B62: 44746 | D62: 622811******7494 | E62: 吉安市分行 | F62: 梅赛德斯-奔驰牌 | G62: 一手自用车 | H62: 直客式 | I62: cd000000000000000000884 | J62: 吉安市 | K62: 44749 | L62: 44749 | M62: 44757 | O62: 2022062880002501 | P62: 赣DFY360 | Q62: 360018057218 | R62: 12 | S62: 3 | T62: 梅洁 | V62: YP360000632302230174
A63: 梁文鸿 | B63: 44748 | D63: 622811******9305 | E63: 吉安市青原大道支行 | F63: 凯迪拉克 | G63: 一手自用车 | H63: 直客式 | I63: cd000000000000000000885 | J63: 吉安市 | K63: 44753 | L63: 44753 | M63: 44757 | O63: 2022070580001705 | P63: 赣D84826 | Q63: 360018072307 | R63: 10 | S63: 3 | T63: 王婷 | V63: YP360000632302230172
...

Sheet 汽车分期 (2)
A1: 业务合同编号 | B1: 客户姓名 | C1: 放款日期 | D1: 联系电话 | E1: 分享卡号 | F1: 归属分支行 | G1: 车辆品牌 | H1: 车辆类型1 | I1: 合作方式2 | J1: 车辆权证编码 | K1: 上牌地 | L1: 车辆产权登记日期 | M1: 抵押登记日期 | N1: 抵押权证入库日期 | O1: 抵押权证出库日期 | P1: 机动车登记编号 | Q1: 机动车登记证书编号 | R1: 抵押金额（万元） | S1: 借款期限 | T1: 客户经理 | U1: 备注 | V1: 押品编号
A2: 2022041280002431 | B2: 曾卫明 | C2: 44665 | D2: 13879636025 | E2: 6228110084348796 | F2: 吉安市青原大道支行 | G2: 凯迪拉克 | H2: 一手自用车 | I2: 直客式 | J2: cd000000000000000000824 | K2: 吉安市 | L2: 44673 | M2: 44673 | N2: 44680 | P2: 赣D676A8 | Q2: 360016785898 | R2: 16 | S2: 5 | T2: 王婷 | U2: 240700 | V2: YP360000632302230232
A3: 2022042680001466 | B3: 范芳云 | C3: 44678 | D3: 13367964455 | E3: 6228110084364314 | F3: 吉安市分行 | G3: 梅赛德斯-奔驰牌 | H3: 一手自用车 | I3: 直客式 | J3: cd000000000000000000825 | K3: 吉安市 | L3: 44680 | M3: 44680 | N3: 44691 | P3: 赣DQ9655 | Q3: 360018864876 | R3: 10 | S3: 3 | T3: 郭玲风 | V3: YP360000632302230231
A4: 2022042580001203 | B4: 刘新美 | C4: 44678 | D4: 19169726378 | E4: 6228110084364256 | F4: 吉安市分行 | G4: 梅赛德斯-奔驰牌 | H4: 一手自用车 | I4: 直客式 | J4: cd000000000000000000826 | K4: 吉安市 | L4: 44679 | M4: 44679 | N4: 44691 | P4: 赣DFD802 | Q4: 360018864890 | R4: 25 | S4: 5 | T4: 郭玲风 | V4: YP360000632302230230
A5: 2022042580003264 | B5: 欧阳军军 | C5: 44678 | D5: 13576888887 | E5: 6228110084364330 | F5: 吉安市分行 | G5: 梅赛德斯-奔驰牌 | H5: 一手自用车 | I5: 直客式 | J5: cd000000000000000000827 | K5: 吉安市 | L5: 44679 | M5: 44679 | N5: 44691 | P5: 赣D22U51 | Q5: 360018864883 | R5: 33 | S5: 5 | T5: 郭玲风 | V5: YP360000632302230229
A6: 2022042580001570 | B6: 尹奕花 | C6: 44679 | D6: 15779619088 | E6: 6228110084367051 | F6: 吉安市分行 | G6: 梅赛德斯-奔驰牌 | H6: 一手自用车 | I6: 直客式 | J6: cd000000000000000000828 | K6: 吉安市 | L6: 44680 | M6: 44680 | N6: 44691 | P6: 赣DGB711 | Q6: 360018864873 | R6: 20 | S6: 5 | T6: 郭玲风 | V6: YP360000632302230228
A7: 2022050780001519 | B7: 颜运林 | C7: 44690 | D7: 15521824043 | E7: 6228110084375484 | F7: 吉安市青原大道支行 | G7: 凯迪拉克 | H7: 一手自用车 | I7: 直客式 | J7: cd000000000000000000829 | K7: 吉安市 | L7: 44690 | M7: 44680 | N7: 44697 | P7: 赣DHT313 | Q7: 360018863228 | R7: 14.9 | S7: 5 | T7: 谢文青 | V7: YP360000632302230227
A8: 2022042980003295 | B8: 赖章红 | C8: 44686 | D8: 13979696853 | E8: 6228110084366780 | F8: 吉安市分行 | G8: 凯迪拉克 | H8: 一手自用车 | I8: 直客式 | J8: cd000000000000000000830 | K8: 吉安市 | L8: 44692 | M8: 44692 | N8: 44697 | P8: 赣DAG326 | Q8: 360016781899 | R8: 22 | S8: 5 | T8: 郭玲风 | V8: YP360000632302230226
A9: 2022051080001878 | B9: 项海珍 | C9: 44693 | D9: 15079668829 | E9: 6228110084380674 | F9: 吉安市分行 | G9: 梅赛德斯-奔驰牌 | H9: 一手自用车 | I9: 直客式 | J9: cd000000000000000000831 | K9: 吉安市 | L9: 44694 | M9: 44694 | N9: 44697 | P9: 赣DIQ388 | Q9: 360018864732 | R9: 24 | S9: 3 | T9: 郭玲风 | V9: YP360000632302230225
A10: 2022051580001032 | B10: 胡阳斌 | C10: 44700 | D10: 18160763149 | E10: 6228110084388800 | F10: 吉安市青原大道支行 | G10: 凯迪拉克 | H10: 一手自用车 | I10: 直客式 | J10: cd000000000000000000832 | K10: 吉安市 | L10: 44699 | M10: 44699 | N10: 44706 | O10: 44775 | P10: 赣DHQ283 | Q10: 360018863277 | R10: 19 | S10: 5 | T10: 谢文青 | V10: YP360000632302230224
A11: 2022051880002193 | B11: 杨敬云 | C11: 44705 | D11: 13397066777 | E11: 6228110084400647 | F11: 吉安市分行 | G11: 梅赛德斯-奔驰牌 | H11: 一手自用车 | I11: 直客式 | J11: cd000000000000000000833 | K11: 吉安市 | L11: 44706 | M11: 44706 | N11: 44708 | P11: 赣DBH607 | Q11: 360018842141 | R11: 47 | S11: 5 | T11: 郭玲风 | V11: YP360000632302230223
A12: 2022052480002606 | B12: 罗晓武 | C12: 44708 | D12: 18507967797 | E12: 6228110084414044 | F12: 吉安市分行 | G12: 梅赛德斯-奔驰牌 | H12: 一手自用车 | I12: 直客式 | J12: cd000000000000000000834 | K12: 吉安市 | L12: 44712 | M12: 44712 | N12: 44714 | P12: 赣DF5096 | Q12: 360018057395 | R12: 28 | S12: 5 | T12: 郭玲风 | V12: YP360000632302230222
A13: 2022052680003454 | B13: 曹江湖 | C13: 44713 | D13: 13237965999 | E13: 6228110084418078 | F13: 吉安市分行 | G13: 梅赛德斯-奔驰牌 | H13: 一手自用车 | I13: 直客式 | J13: cd000000000000000000835 | K13: 吉安市 | L13: 44714 | M13: 44714 | N13: 44722 | P13: 赣DFQ557 | Q13: 360018842159 | R13: 70 | S13: 5 | T13: 梅洁 | V13: YP360000632302230221
A14: 2022060180002955 | B14: 刘金秀 | C14: 44718 | D14: 15107910552 | E14: 6228110084421908 | F14: 吉安市分行 | G14: 梅赛德斯-奔驰牌 | H14: 一手自用车 | I14: 直客式 | J14: cd000000000000000000836 | K14: 吉安市 | L14: 44719 | M14: 44719 | N14: 44722 | P14: 赣DCG225 | Q14: 360018057160 | R14: 20 | S14: 4 | T14: 梅洁 | V14: YP360000632302230220
A15: 2022060780002506 | B15: 夏候耀鹏 | C15: 44720 | D15: 13033297463 | E15: 6228110084434620 | F15: 吉安市青原大道支行 | G15: 凯迪拉克 | H15: 一手自用车 | I15: 直客式 | J15: cd000000000000000000837 | K15: 吉安市 | L15: 44720 | M15: 44720 | N15: 44729 | P15: 赣D7IY77 | Q15: 360018858671 | R15: 10 | S15: 3 | T15: 谢文青 | V15: YP360000632302230217
A16: 2022052780004503 | B16: 张连文 | C16: 44712 | D16: 18321635592 | E16: 6228110084422195 | F16: 吉安市青原大道支行 | G16: 凯迪拉克 | H16: 一手自用车 | I16: 直客式 | J16: cd000000000000000000838 | K16: 吉安市 | L16: 44713 | M16: 44713 | N16: 44729 | P16: 赣DDA652 | Q16: 360018858782 | R16: 10 | S16: 5 | T16: 王婷 | V16: YP360000632302230209
A17: 2022052380003438 | B17: 杨玲 | C17: 44719 | D17: 15970232023 | E17: 6228110084407311 | F17: 吉安市分行 | G17: 梅赛德斯-奔驰牌 | H17: 一手自用车 | I17: 直客式 | J17: cd000000000000000000839 | K17: 吉安市 | L17: 44719 | M17: 44719 | N17: 44729 | P17: 赣DFY367 | Q17: 360018057423 | R17: 22.5 | S17: 5 | T17: 郭玲风 | V17: YP360000632302230219
A18: 2022060480000553 | B18: 张飘兵 | C18: 44722 | D18: 15907960601 | E18: 6228110084441385 | F18: 吉安市分行 | G18: 梅赛德斯-奔驰牌 | H18: 一手自用车 | I18: 直客式 | J18: cd000000000000000000840 | K18: 吉安市 | L18: 44725 | M18: 44725 | N18: 44729 | P18: 赣DM1360 | Q18: 360018859242 | R18: 50 | S18: 4 | T18: 梅洁 | V18: YP360000632302230218
A19: 2022060980005184 | B19: 曾钦湖 | C19: 44722 | D19: 19907993218 | E19: 6228110084447200 | F19: 吉安市城北支行 | G19: 凯迪拉克 | H19: 一手自用车 | I19: 直客式 | J19: cd000000000000000000841 | K19: 萍乡市 | L19: 44726 | M19: 44726 | N19: 44739 | P19: 赣JE0307 | Q19: 360017035866 | R19: 15 | S19: 3 | T19: 周颖 | V19: YP360000632302230215
A20: 2022060780002698 | B20: 刘云甫 | C20: 44722 | D20: 13979628258 | E20: 6228110084441617 | F20: 吉安市分行 | G20: 梅赛德斯-奔驰牌 | H20: 一手自用车 | I20: 直客式 | J20: cd000000000000000000842 | K20: 吉安市 | L20: 44727 | M20: 44727 | N20: 44739 | P20: 赣D16Z89 | Q20: 360018057308 | R20: 30 | S20: 5 | T20: 梅洁 | V20: YP360000632302230216
A21: 2022061380002260 | B21: 段德泓 | C21: 44726 | D21: 18870659464 | E21: 6228110084449925 | F21: 吉安市城北支行 | G21: 奥迪牌 | H21: 一手自用车 | I21: 直客式 | J21: cd000000000000000000843 | K21: 吉安市 | L21: 44727 | M21: 44727 | N21: 44739 | P21: 赣D01S70 | Q21: 360018072842 | R21: 15 | S21: 3 | T21: 徐求芸 | V21: YP360000632302230213
A22: 2022061080003441 | B22: 刘益平 | C22: 44726 | D22: 13929052766 | E22: 6228110084444587 | F22: 吉安市城北支行 | G22: 奥迪牌 | H22: 一手自用车 | I22: 直客式 | J22: cd000000000000000000844 | K22: 吉安市 | L22: 44727 | M22: 44727 | N22: 44739 | P22: 赣DFY922 | Q22: 360018072833 | R22: 14.98 | S22: 3 | T22: 徐求芸 | V22: YP360000632302230214
A23: 2022061380001757 | B23: 戴平 | C23: 44726 | D23: 13879631787 | E23: 6228110084454404 | F23: 吉安市青原大道支行 | G23: 凯迪拉克 | H23: 一手自用车 | I23: 直客式 | J23: cd000000000000000000845 | K23: 吉安市 | L23: 44727 | M23: 44727 | N23: 44739 | P23: 赣D96V15 | Q23: 360018858504 | R23: 10 | S23: 5 | T23: 谢文青 | V23: YP360000632302230212
A24: 2022061280000375 | B24: 刘舟 | C24: 44727 | D24: 15170206904 | E24: 6228110084450857 | F24: 吉安市青原大道支行 | G24: 凯迪拉克 | H24: 一手自用车 | I24: 直客式 | J24: cd000000000000000000846 | K24: 吉安市 | L24: 44727 | M24: 44727 | N24: 44739 | P24: 赣DFM638 | Q24: 360018858886 | R24: 15 | S24: 5 | T24: 谢文青 | V24: YP360000632302230211
A25: 2022060780003220 | B25: 周子燕 | C25: 44720 | D25: 13979641188 | E25: 6228110084434760 | F25: 吉安市青原大道支行 | G25: 沃尔沃 | H25: 一手自用车 | I25: 直客式 | J25: cd000000000000000000847 | K25: 吉安市 | L25: 44727 | M25: 44727 | N25: 44739 | P25: 赣D3551W | Q25: 360016712168 | R25: 17 | S25: 3 | T25: 王婷 | V25: YP360000632302230210
A26: 2022061780003464 | B26: 姚亮 | C26: 44732 | D26: 18107061010 | E26: 6228110084469204 | F26: 吉安市青原大道支行 | G26: 丰田牌 | H26: 一手自用车 | I26: 直客式 | J26: cd000000000000000000848 | K26: 吉安市 | L26: 44732 | M26: 44732 | N26: 44739 | P26: 赣D5207M | Q26: 360018057440 | R26: 15 | S26: 3 | T26: 谢文青 | V26: YP360000632302230207
A27: 2022061380001705 | B27: 冯秋根 | C27: 44727 | D27: 13879654628 | E27: 6228110084459015 | F27: 吉安市青原大道支行 | G27: 凯迪拉克 | H27: 一手自用车 | I27: 直客式 | J27: cd000000000000000000849 | K27: 吉安市 | L27: 44728 | M27: 44728 | N27: 44739 | P27: 赣DE1888 | Q27: 360018858878 | R27: 27 | S27: 5 | T27: 谢文青 | V27: YP360000632302230206
... A51: 2022061480001852 | B51: 肖少敏 | C51: 44727 | D51: 13907961276 | E51: 6228110084455492 | F51: 吉安市城北支行 | G51: 奥迪牌 | H51: 一手自用车 | I51: 直客式 | J51: cd000000000000000000873 | K51: 吉安市 | L51: 44736 | M51: 44736 | N51: 44750 | P51: 赣D1Q888 | Q51: 360018072922 | R51: 15 | S51: 3 | T51: 周颖 | V51: YP360000632302230187
A52: 2022062980002904 | B52: 黄丽萍 | C52: 44746 | E52: 622811******5022 | F52: 吉安市分行 | G52: 梅赛德斯-奔驰牌 | H52: 一手自用车 | I52: 直客式 | J52: cd000000000000000000874 | K52: 吉安市 | L52: 44746 | M52: 44746 | N52: 44750 | P52: 赣DGF877 | Q52: 360018057296 | R52: 35.8 | S52: 5 | T52: 梅洁 | V52: YP360000632302230183
A53: 2022062880003946 | B53: 罗亮 | C53: 44742 | D53: 15179629668 | E53: 6228110084503481 | F53: 吉安市分行 | G53: 梅赛德斯-奔驰牌 | H53: 一手自用车 | I53: 直客式 | J53: cd000000000000000000875 | K53: 吉安市 | L53: 44746 | M53: 44746 | N53: 44750 | P53: 赣DL8800 | Q53: 360018057058 | R53: 35 | S53: 5 | T53: 梅洁 | V53: YP360000632302230182
A54: 2022062980001609 | B54: 涂林荣 | C54: 44742 | D54: 13970672798 | E54: 6228110084501899 | F54: 吉安市分行 | G54: 梅赛德斯-奔驰牌 | H54: 一手自用车 | I54: 直客式 | J54: cd000000000000000000876 | K54: 吉安市 | L54: 44746 | M54: 44746 | N54: 44750 | P54: 赣DDV772 | Q54: 360018057064 | R54: 24.58 | S54: 5 | T54: 梅洁 | V54: YP360000632207080001
A55: 2022062980000539 | B55: 肖辉 | C55: 44741 | D55: 13600189334 | E55: 6228110084505163 | F55: 吉安市青原大道支行 | G55: 凯迪拉克 | H55: 一手自用车 | I55: 直客式 | J55: cd000000000000000000877 | K55: 吉安市 | L55: 44741 | M55: 44741 | N55: 44754 | P55: 赣DEC011 | Q55: 360018072394 | R55: 15 | S55: 5 | T55: 谢文青 | V55: YP360000632302230181
A56: 2022062880001586 | B56: 颜轶群 | C56: 44740 | D56: 18779619192 | E56: 6228110084499300 | F56: 吉安市青原大道支行 | G56: 领克 | H56: 一手自用车 | I56: 直客式 | J56: cd000000000000000000878 | K56: 吉安市 | L56: 44741 | M56: 44741 | N56: 44754 | P56: 赣DNG965 | Q56: 360018873720 | R56: 15 | S56: 5 | T56: 谢文青 | V56: YP360000632302230180
A57: 2022062080002875 | B57: 杨舟 | C57: 44742 | D57: 15949689119 | E57: 6228110084471572 | F57: 吉安市青原大道支行 | G57: 凯迪拉克 | H57: 一手自用车 | I57: 直客式 | J57: cd000000000000000000879 | K57: 吉安市 | L57: 44746 | M57: 44746 | N57: 44754 | P57: 赣DHX298 | Q57: 360018866266 | R57: 15 | S57: 5 | T57: 谢文青 | V57: YP360000632302230179
A58: 2022062780001742 | B58: 刘金明 | C58: 44746 | E58: 622811******8435 | F58: 吉安市青原大道支行 | G58: 凯迪拉克 | H58: 一手自用车 | I58: 直客式 | J58: cd000000000000000000880 | K58: 吉安市 | L58: 44746 | M58: 44746 | N58: 44754 | P58: 赣DHP001 | Q58: 360018072464 | R58: 20 | S58: 5 | T58: 谢文青 | V58: YP360000632302230178
A59: 2022062980000539 | B59: 肖俊 | C59: 44741 | E59: 622811******5163 | F59: 吉安市青原大道支行 | G59: 凯迪拉克 | H59: 一手自用车 | I59: 直客式 | J59: cd000000000000000000881 | K59: 吉安市 | L59: 44742 | M59: 44742 | N59: 44754 | P59: 赣DEH239 | Q59: 360018835997 | R59: 15 | S59: 5 | T59: 谢文青 | V59: YP360000632302230181
A60: 2022062880002023 | B60: 易莉 | C60: 44741 | D60: 13319343334 | E60: 6228110084503200 | F60: 吉安市青原大道支行 | G60: 凯迪拉克 | H60: 一手自用车 | I60: 直客式 | J60: cd000000000000000000882 | K60: 宜春市 | L60: 44748 | M60: 44748 | N60: 44757 | P60: 赣CPA167 | Q60: 360014956976 | R60: 15 | S60: 5 | T60: 谢文青 | V60: YP360000632302230164
A61: 2022070780002566 | B61: 黄文豪 | C61: 44753 | E61: 622811******8893 | F61: 吉安市分行 | G61: 梅赛德斯-奔驰牌 | H61: 一手自用车 | I61: 直客式 | J61: cd000000000000000000883 | K61: 吉安市 | L61: 44753 | M61: 44753 | N61: 44757 | P61: 赣D9852N | Q61: 360018057328 | R61: 10 | S61: 3 | T61: 梅洁 | V61: YP360000632302230175
A62: 2022062880002501 | B62: 刘富根 | C62: 44746 | E62: 622811******7494 | F62: 吉安市分行 | G62: 梅赛德斯-奔驰牌 | H62: 一手自用车 | I62: 直客式 | J62: cd000000000000000000884 | K62: 吉安市 | L62: 44749 | M62: 44749 | N62: 44757 | P62: 赣DFY360 | Q62: 360018057218 | R62: 12 | S62: 3 | T62: 梅洁 | V62: YP360000632302230174
A63: 2022070580001705 | B63: 梁文鸿 | C63: 44748 | E63: 622811******9305 | F63: 吉安市青原大道支行 | G63: 凯迪拉克 | H63: 一手自用车 | I63: 直客式 | J63: cd000000000000000000885 | K63: 吉安市 | L63: 44753 | M63: 44753 | N63: 44757 | P63: 赣D84826 | Q63: 360018072307 | R63: 10 | S63: 3 | T63: 王婷 | V63: YP360000632302230172
...
